Workbook

Sheet Hypotheses
A1: HEAVEN — Hypothèses modèle financier v1
A2: Sqwensy (BE) — Avril 2026 — Cellules BLEUES = inputs modifiables — JAUNES = assumptions clés
A4: 1. PRICING & FUNNEL FANVUE
A5: Panier moyen PPV (USD) | B5: 18 | C5: Mix packs 15-35 $ + tips
A6: Taux d'achat PPV mensuel / abonné actif | B6: 0.04 | C6: Benchmark freemium adult. À mesurer dès M2.
A7: % abonnés « actifs » (1 interaction / mois) | B7: 0.45 | C7: Abonnés free engagés vs inactifs
A8: Commission Fanvue | B8: 0.15 | C8: Standard plateforme
A9: Taux conversion USD → EUR | B9: 0.92 | C9: À ajuster au taux BNB en clôture
A11: 2. RÉMUNÉRATION MODÈLES
A12: Part Mode B — Slot 1 (% du net distribuable) | B12: 0.7 | C12: 70 % modèle, 30 % Sqwensy — renégociable
A13: Part Mode B — Slot 2 (% du net distribuable) | B13: 0.7 | C13: Identique Slot 1
A14: Part « modèle » Mode A — Persona IA (= 0) | B14: 0 | C14: Mode A = 100 % Sqwensy, aucune redistribution
A16: 3. FRAIS DE PRODUCTION MENSUELS (EUR)
A17: Frais prod Mode A — Persona IA / mois | B17: 80 | C17: Outils IA (Midjourney, Suno, ComfyUI) + stockage
A18: Frais prod Mode B — Slot 1 / mois | B18: 120 | C18: Shooting, montage, habillage IA si applicable
A19: Frais prod Mode B — Slot 2 / mois | B19: 120 | C19: Idem Slot 1
A21: 4. FRAIS FIXES SQWENSY-HEAVEN (EUR / mois)
A22: Hosting (Supabase, Vercel, R2) | B22: 25 | C22: Free tier jusqu'à ~M6, puis upgrade
A23: Outils automation / agent IA (API, n8n) | B23: 40 | C23: Self-host + API OpenAI/Anthropic
A24: Domaines + misc tech | B24: 10
A25: Provision juridique/comptable | B25: 80 | C25: Lissé : contrats + revue comptable périodique
A27: 5. BUDGET INITIAL & TRÉSORERIE
A28: Apport initial (EUR) | B28: 2000 | C28: Contrainte bootstrap
A29: Trésorerie minimale cible (mois de charges fixes) | B29: 3 | C29: Alerte si < 3 mois
A31: 6. FISCALITÉ BELGIQUE (À VALIDER comptable)
A32: Seuil franchise TVA BE (EUR HT/an) | B32: 25000 | C32: Bascule TVA 21 % au-delà
A33: TVA applicable sur revenus Fanvue (0=non, 1=oui) | B33: 0 | C33: Fanvue UK post-Brexit → probable exonération B2B. À VALIDER.
A34: Taux ISOC réduit PME (≤ 100 k€ bénéf.) | B34: 0.2 | C34: Conditions PME à respecter
A35: Taux ISOC standard (> 100 k€) | B35: 0.25
A36: Cotisations INASTI indépendant complémentaire | B36: 0.205 | C36: Approximation. Seuils et plafonds variables.
A37: Plafond droit à l'image par modèle (EUR/an) | B37: 9875 | C37: Chiffre 2024-2025 indicatif — À VALIDER 2026
A39: 7. RAMPE ABONNÉS FREE FANVUE (SCÉNARIO MÉDIAN)
A40: Mode A — abonnés mois 1 | B40: 80 | C40: Démarrage organique IG/TikTok
A41: Mode A — nouveaux abonnés / mois (M2+) | B41: 150 | C41: Rampe moyenne
A42: Mode B Slot 1 — mois de démarrage | B42: 4 | C42: Arrive après validation Mode A
A43: Mode B Slot 1 — nouveaux abonnés / mois | B43: 130
A44: Mode B Slot 2 — mois de démarrage | B44: 5
A45: Mode B Slot 2 — nouveaux abonnés / mois | B45: 120
A47: 8. CAMING — CANAL D'ACQUISITION PRIMAIRE (Mode B)
A48: Caming activé Slot 1 (1=oui, 0=non) | B48: 1 | C48: Si 1, boost rampe Slot 1 via funnel live
...

Sheet PL_24mois
A1: HEAVEN — P&L mensuel 24 mois (scénario médian)
A2: EUR sauf indication. Formules noires, inputs externes en vert.
A4: Mois | B4: M1 | C4: M2 | D4: M3 | E4: M4 | F4: M5 | G4: M6 | H4: M7 | I4: M8 | J4: M9 | K4: M10 | L4: M11 | M4: M12 | N4: M13 | O4: M14 | P4: M15 | Q4: M16 | R4: M17 | S4: M18 | T4: M19 | U4: M20 | V4: M21 | W4: M22 | X4: M23 | Y4: M24 | Z4: Total 24M
A5: ABONNÉS FREE FANVUE (cumulés)
A6: Mode A — Persona IA (cumulé) | B6: =Hypotheses!$B$40 -> 80 | C6: =B6+Hypotheses!$B$41 -> 230 | D6: =C6+Hypotheses!$B$41 -> 380 | E6: =D6+Hypotheses!$B$41 -> 530 | F6: =E6+Hypotheses!$B$41 -> 680 | G6: =F6+Hypotheses!$B$41 -> 830 | H6: =G6+Hypotheses!$B$41 -> 980 | I6: =H6+Hypotheses!$B$41 -> 1130 | J6: =I6+Hypotheses!$B$41 -> 1280 | ... Y6: =X6+Hypotheses!$B$41 -> 3530 | Z6: — (stock)
A7: Mode B — Slot 1 (cumulé, organique + caming) | B7: =IF(1>=Hypotheses!$B$42,(Hypotheses!$B$43+Hypotheses!$B$48*Hypotheses!$B$50*4.33*Hypotheses!$B$51*Hypotheses!$B$52*(1-Hypotheses!$B$53))*(1-Hypotheses!$B$42+1),0) -> 0 | C7: =IF(2>=Hypotheses!$B$42,B7+(Hypotheses!$B$43+Hypotheses!$B$48*Hypotheses!$B$50*4.33*Hypotheses!$B$51*Hypotheses!$B$52*(1-Hypotheses!$B$53)),0) -> 0 | D7: =IF(3>=Hypotheses!$B$42,C7+(Hypotheses!$B$43+Hypotheses!$B$48*Hypotheses!$B$50*4.33*Hypotheses!$B$51*Hypotheses!$B$52*(1-Hypotheses!$B$53)),0) -> 0 | E7: =IF(4>=Hypotheses!$B$42,D7+(Hypotheses!$B$43+Hypotheses!$B$48*Hypotheses!$B$50*4.33*Hypotheses!$B$51*Hypotheses!$B$52*(1-Hypotheses!$B$53)),0) -> 198.5872 | F7: =IF(5>=Hypotheses!$B$42,E7+(Hypotheses!$B$43+Hypotheses!$B$48*Hypotheses!$B$50*4.33*Hypotheses!$B$51*Hypotheses!$B$52*(1-Hypotheses!$B$53)),0) -> 397.1744 | G7: =IF(6>=Hypotheses!$B$42,F7+(Hypotheses!$B$43+Hypotheses!$B$48*Hypotheses!$B$50*4.33*Hypotheses!$B$51*Hypotheses!$B$52*(1-Hypotheses!$B$53)),0) -> 595.7616 | H7: =IF(7>=Hypotheses!$B$42,G7+(Hypotheses!$B$43+Hypotheses!$B$48*Hypotheses!$B$50*4.33*Hypotheses!$B$51*Hypotheses!$B$52*(1-Hypotheses!$B$53)),0) -> 794.3488 | I7: =IF(8>=Hypotheses!$B$42,H7+(Hypotheses!$B$43+Hypotheses!$B$48*Hypotheses!$B$50*4.33*Hypotheses!$B$51*Hypotheses!$B$52*(1-Hypotheses!$B$53)),0) -> 992.936 | J7: =IF(9>=Hypotheses!$B$42,I7+(Hypotheses!$B$43+Hypotheses!$B$48*Hypotheses!$B$50*4.33*Hypotheses!$B$51*Hypotheses!$B$52*(1-Hypotheses!$B$53)),0) -> 1191.5232 | K7: =IF(10>=Hypotheses!$B$42,J7+(Hypotheses!$B$43+Hypotheses!$B$48*Hypotheses!$B$50*4.33*Hypotheses!$B$51*Hypotheses!$B$52*(1-Hypotheses!$B$53)),0) -> 1390.1104 | L7: =IF(11>=Hypotheses!$B$42,K7+(Hypotheses!$B$43+Hypotheses!$B$48*Hypotheses!$B$50*4.33*Hypotheses!$B$51*Hypotheses!$B$52*(1-Hypotheses!$B$53)),0) -> 1588.6976 | M7: =IF(12>=Hypotheses!$B$42,L7+(Hypotheses!$B$43+Hypotheses!$B$48*Hypotheses!$B$50*4.33*Hypotheses!$B$51*Hypotheses!$B$52*(1-Hypotheses!$B$53)),0) -> 1787.2848 | N7: =IF(13>=Hypotheses!$B$42,M7+(Hypotheses!$B$43+Hypotheses!$B$48*Hypotheses!$B$50*4.33*Hypotheses!$B$51*Hypotheses!$B$52*(1-Hypotheses!$B$53)),0) -> 1985.872 | O7: =IF(14>=Hypotheses!$B$42,N7+(Hypotheses!$B$43+Hypotheses!$B$48*Hypotheses!$B$50*4.33*Hypotheses!$B$51*Hypotheses!$B$52*(1-Hypotheses!$B$53)),0) -> 2184.4592 | P7: =IF(15>=Hypotheses!$B$42,O7+(Hypotheses!$B$43+Hypotheses!$B$48*Hypotheses!$B$50*4.33*Hypotheses!$B$51*Hypotheses!$B$52*(1-Hypotheses!$B$53)),0) -> 2383.0464 | Q7: =IF(16>=Hypotheses!$B$42,P7+(Hypotheses!$B$43+Hypotheses!$B$48*Hypotheses!$B$50*4.33*Hypotheses!$B$51*Hypotheses!$B$52*(1-Hypotheses!$B$53)),0) -> 2581.6336 | R7: =IF(17>=Hypotheses!$B$42,Q7+(Hypotheses!$B$43+Hypotheses!$B$48*Hypotheses!$B$50*4.33*Hypotheses!$B$51*Hypotheses!$B$52*(1-Hypotheses!$B$53)),0) -> 2780.2208 | S7: =IF(18>=Hypotheses!$B$42,R7+(Hypotheses!$B$43+Hypotheses!$B$48*Hypotheses!$B$50*4.33*Hypotheses!$B$51*Hypotheses!$B$52*(1-Hypotheses!$B$53)),0) -> 2978.808 | T7: =IF(19>=Hypotheses!$B$42,S7+(Hypotheses!$B$43+Hypotheses!$B$48*Hypotheses!$B$50*4.33*Hypotheses!$B$51*Hypotheses!$B$52*(1-Hypotheses!$B$53)),0) -> 3177.3952 | U7: =IF(20>=Hypotheses!$B$42,T7+(Hypotheses!$B$43+Hypotheses!$B$48*Hypotheses!$B$50*4.33*Hypotheses!$B$51*Hypotheses!$B$52*(1-Hypotheses!$B$53)),0) -> 3375.9824 | V7: =IF(21>=Hypotheses!$B$42,U7+(Hypotheses!$B$43+Hypotheses!$B$48*Hypotheses!$B$50*4.33*Hypotheses!$B$51*Hypotheses!$B$52*(1-Hypotheses!$B$53)),0) -> 3574.5696 | W7: =IF(22>=Hypotheses!$B$42,V7+(Hypotheses!$B$43+Hypotheses!$B$48*Hypotheses!$B$50*4.33*Hypotheses!$B$51*Hypotheses!$B$52*(1-Hypotheses!$B$53)),0) -> 3773.1568 | X7: =IF(23>=Hypotheses!$B$42,W7+(Hypotheses!$B$43+Hypotheses!$B$48*Hypotheses!$B$50*4.33*Hypotheses!$B$51*Hypotheses!$B$52*(1-Hypotheses!$B$53)),0) -> 3971.744 | Y7: =IF(24>=Hypotheses!$B$42,X7+(Hypotheses!$B$43+Hypotheses!$B$48*Hypotheses!$B$50*4.33*Hypotheses!$B$51*Hypotheses!$B$52*(1-Hypotheses!$B$53)),0) -> 4170.3312 | Z7: — (stock)
A8: Mode B — Slot 2 (cumulé, organique + caming) | B8: =IF(1>=Hypotheses!$B$44,(Hypotheses!$B$45+Hypotheses!$B$49*Hypotheses!$B$50*4.33*Hypotheses!$B$51*Hypotheses!$B$52*(1-Hypotheses!$B$53))*(1-Hypotheses!$B$44+1),0) -> 0 | C8: =IF(2>=Hypotheses!$B$44,B8+(Hypotheses!$B$45+Hypotheses!$B$49*Hypotheses!$B$50*4.33*Hypotheses!$B$51*Hypotheses!$B$52*(1-Hypotheses!$B$53)),0) -> 0 | D8: =IF(3>=Hypotheses!$B$44,C8+(Hypotheses!$B$45+Hypotheses!$B$49*Hypotheses!$B$50*4.33*Hypotheses!$B$51*Hypotheses!$B$52*(1-Hypotheses!$B$53)),0) -> 0 | E8: =IF(4>=Hypotheses!$B$44,D8+(Hypotheses!$B$45+Hypotheses!$B$49*Hypotheses!$B$50*4.33*Hypotheses!$B$51*Hypotheses!$B$52*(1-Hypotheses!$B$53)),0) -> 0 | F8: =IF(5>=Hypotheses!$B$44,E8+(Hypotheses!$B$45+Hypotheses!$B$49*Hypotheses!$B$50*4.33*Hypotheses!$B$51*Hypotheses!$B$52*(1-Hypotheses!$B$53)),0) -> 188.5872 | G8: =IF(6>=Hypotheses!$B$44,F8+(Hypotheses!$B$45+Hypotheses!$B$49*Hypotheses!$B$50*4.33*Hypotheses!$B$51*Hypotheses!$B$52*(1-Hypotheses!$B$53)),0) -> 377.1744 | H8: =IF(7>=Hypotheses!$B$44,G8+(Hypotheses!$B$45+Hypotheses!$B$49*Hypotheses!$B$50*4.33*Hypotheses!$B$51*Hypotheses!$B$52*(1-Hypotheses!$B$53)),0) -> 565.7616 | I8: =IF(8>=Hypotheses!$B$44,H8+(Hypotheses!$B$45+Hypotheses!$B$49*Hypotheses!$B$50*4.33*Hypotheses!$B$51*Hypotheses!$B$52*(1-Hypotheses!$B$53)),0) -> 754.3488 | J8: =IF(9>=Hypotheses!$B$44,I8+(Hypotheses!$B$45+Hypotheses!$B$49*Hypotheses!$B$50*4.33*Hypotheses!$B$51*Hypotheses!$B$52*(1-Hypotheses!$B$53)),0) -> 942.936 | K8: =IF(10>=Hypotheses!$B$44,J8+(Hypotheses!$B$45+Hypotheses!$B$49*Hypotheses!$B$50*4.33*Hypotheses!$B$51*Hypotheses!$B$52*(1-Hypotheses!$B$53)),0) -> 1131.5232 | L8: =IF(11>=Hypotheses!$B$44,K8+(Hypotheses!$B$45+Hypotheses!$B$49*Hypotheses!$B$50*4.33*Hypotheses!$B$51*Hypotheses!$B$52*(1-Hypotheses!$B$53)),0) -> 1320.1104 | M8: =IF(12>=Hypotheses!$B$44,L8+(Hypotheses!$B$45+Hypotheses!$B$49*Hypotheses!$B$50*4.33*Hypotheses!$B$51*Hypotheses!$B$52*(1-Hypotheses!$B$53)),0) -> 1508.6976 | N8: =IF(13>=Hypotheses!$B$44,M8+(Hypotheses!$B$45+Hypotheses!$B$49*Hypotheses!$B$50*4.33*Hypotheses!$B$51*Hypotheses!$B$52*(1-Hypotheses!$B$53)),0) -> 1697.2848 | O8: =IF(14>=Hypotheses!$B$44,N8+(Hypotheses!$B$45+Hypotheses!$B$49*Hypotheses!$B$50*4.33*Hypotheses!$B$51*Hypotheses!$B$52*(1-Hypotheses!$B$53)),0) -> 1885.872 | P8: =IF(15>=Hypotheses!$B$44,O8+(Hypotheses!$B$45+Hypotheses!$B$49*Hypotheses!$B$50*4.33*Hypotheses!$B$51*Hypotheses!$B$52*(1-Hypotheses!$B$53)),0) -> 2074.4592 | Q8: =IF(16>=Hypotheses!$B$44,P8+(Hypotheses!$B$45+Hypotheses!$B$49*Hypotheses!$B$50*4.33*Hypotheses!$B$51*Hypotheses!$B$52*(1-Hypotheses!$B$53)),0) -> 2263.0464 | R8: =IF(17>=Hypotheses!$B$44,Q8+(Hypotheses!$B$45+Hypotheses!$B$49*Hypotheses!$B$50*4.33*Hypotheses!$B$51*Hypotheses!$B$52*(1-Hypotheses!$B$53)),0) -> 2451.6336 | S8: =IF(18>=Hypotheses!$B$44,R8+(Hypotheses!$B$45+Hypotheses!$B$49*Hypotheses!$B$50*4.33*Hypotheses!$B$51*Hypotheses!$B$52*(1-Hypotheses!$B$53)),0) -> 2640.2208 | T8: =IF(19>=Hypotheses!$B$44,S8+(Hypotheses!$B$45+Hypotheses!$B$49*Hypotheses!$B$50*4.33*Hypotheses!$B$51*Hypotheses!$B$52*(1-Hypotheses!$B$53)),0) -> 2828.808 | U8: =IF(20>=Hypotheses!$B$44,T8+(Hypotheses!$B$45+Hypotheses!$B$49*Hypotheses!$B$50*4.33*Hypotheses!$B$51*Hypotheses!$B$52*(1-Hypotheses!$B$53)),0) -> 3017.3952 | V8: =IF(21>=Hypotheses!$B$44,U8+(Hypotheses!$B$45+Hypotheses!$B$49*Hypotheses!$B$50*4.33*Hypotheses!$B$51*Hypotheses!$B$52*(1-Hypotheses!$B$53)),0) -> 3205.9824 | W8: =IF(22>=Hypotheses!$B$44,V8+(Hypotheses!$B$45+Hypotheses!$B$49*Hypotheses!$B$50*4.33*Hypotheses!$B$51*Hypotheses!$B$52*(1-Hypotheses!$B$53)),0) -> 3394.5696 | X8: =IF(23>=Hypotheses!$B$44,W8+(Hypotheses!$B$45+Hypotheses!$B$49*Hypotheses!$B$50*4.33*Hypotheses!$B$51*Hypotheses!$B$52*(1-Hypotheses!$B$53)),0) -> 3583.1568 | Y8: =IF(24>=Hypotheses!$B$44,X8+(Hypotheses!$B$45+Hypotheses!$B$49*Hypotheses!$B$50*4.33*Hypotheses!$B$51*Hypotheses!$B$52*(1-Hypotheses!$B$53)),0) -> 3771.744 | Z8: — (stock)
A9: Total abonnés (cumulé) | B9: =B6+B7+B8 -> 80 | C9: =C6+C7+C8 -> 230 | D9: =D6+D7+D8 -> 380 | E9: =E6+E7+E8 -> 728.5872 | F9: =F6+F7+F8 -> 1265.7616 | G9: =G6+G7+G8 -> 1802.936 | H9: =H6+H7+H8 -> 2340.1104 | I9: =I6+I7+I8 -> 2877.2848 | ... Y9: =Y6+Y7+Y8 -> 11472.075 | Z9: — (stock)
A10: REVENUS BRUTS FANVUE
A11: Revenu brut Mode A (USD) | B11: =B6*Hypotheses!$B$7*Hypotheses!$B$6*Hypotheses!$B$5 -> 25.92 | C11: =C6*Hypotheses!$B$7*Hypotheses!$B$6*Hypotheses!$B$5 -> 74.52 | D11: =D6*Hypotheses!$B$7*Hypotheses!$B$6*Hypotheses!$B$5 -> 123.12 | E11: =E6*Hypotheses!$B$7*Hypotheses!$B$6*Hypotheses!$B$5 -> 171.72 | F11: =F6*Hypotheses!$B$7*Hypotheses!$B$6*Hypotheses!$B$5 -> 220.32 | G11: =G6*Hypotheses!$B$7*Hypotheses!$B$6*Hypotheses!$B$5 -> 268.92 | H11: =H6*Hypotheses!$B$7*Hypotheses!$B$6*Hypotheses!$B$5 -> 317.52 | I11: =I6*Hypotheses!$B$7*Hypotheses!$B$6*Hypotheses!$B$5 -> 366.12 | ... Y11: =Y6*Hypotheses!$B$7*Hypotheses!$B$6*Hypotheses!$B$5 -> 1143.72 | Z11: =SUM(B11:Y11) -> 14035.68
A12: Revenu brut Mode B Slot 1 (USD) | B12: =B7*Hypotheses!$B$7*Hypotheses!$B$6*Hypotheses!$B$5 -> 0 | C12: =C7*Hypotheses!$B$7*Hypotheses!$B$6*Hypotheses!$B$5 -> 0 | D12: =D7*Hypotheses!$B$7*Hypotheses!$B$6*Hypotheses!$B$5 -> 0 | E12: =E7*Hypotheses!$B$7*Hypotheses!$B$6*Hypotheses!$B$5 -> 64.342253 | F12: =F7*Hypotheses!$B$7*Hypotheses!$B$6*Hypotheses!$B$5 -> 128.68451 | G12: =G7*Hypotheses!$B$7*Hypotheses!$B$6*Hypotheses!$B$5 -> 193.02676 | H12: =H7*Hypotheses!$B$7*Hypotheses!$B$6*Hypotheses!$B$5 -> 257.36901 | I12: =I7*Hypotheses!$B$7*Hypotheses!$B$6*Hypotheses!$B$5 -> 321.71126 | ... Y12: =Y7*Hypotheses!$B$7*Hypotheses!$B$6*Hypotheses!$B$5 -> 1351.1873 | Z12: =SUM(B12:Y12) -> 14863.06
A13: Revenu brut Mode B Slot 2 (USD) | B13: =B8*Hypotheses!$B$7*Hypotheses!$B$6*Hypotheses!$B$5 -> 0 | C13: =C8*Hypotheses!$B$7*Hypotheses!$B$6*Hypotheses!$B$5 -> 0 | D13: =D8*Hypotheses!$B$7*Hypotheses!$B$6*Hypotheses!$B$5 -> 0 | E13: =E8*Hypotheses!$B$7*Hypotheses!$B$6*Hypotheses!$B$5 -> 0 | F13: =F8*Hypotheses!$B$7*Hypotheses!$B$6*Hypotheses!$B$5 -> 61.102253 | G13: =G8*Hypotheses!$B$7*Hypotheses!$B$6*Hypotheses!$B$5 -> 122.20451 | H13: =H8*Hypotheses!$B$7*Hypotheses!$B$6*Hypotheses!$B$5 -> 183.30676 | I13: =I8*Hypotheses!$B$7*Hypotheses!$B$6*Hypotheses!$B$5 -> 244.40901 | ... Y13: =Y8*Hypotheses!$B$7*Hypotheses!$B$6*Hypotheses!$B$5 -> 1222.0451 | Z13: =SUM(B13:Y13) -> 12831.473
A14: Total brut Fanvue (USD) | B14: =B11+B12+B13 -> 25.92 | C14: =C11+C12+C13 -> 74.52 | D14: =D11+D12+D13 -> 123.12 | E14: =E11+E12+E13 -> 236.06225 | F14: =F11+F12+F13 -> 410.10676 | G14: =G11+G12+G13 -> 584.15126 | H14: =H11+H12+H13 -> 758.19577 | I14: =I11+I12+I13 -> 932.24028 | ... Y14: =Y11+Y12+Y13 -> 3716.9524 | Z14: =SUM(B14:Y14) -> 41730.213
A15: Total brut Fanvue (EUR) | B15: =B14*Hypotheses!$B$9 -> 23.8464 | C15: =C14*Hypotheses!$B$9 -> 68.5584 | D15: =D14*Hypotheses!$B$9 -> 113.2704 | E15: =E14*Hypotheses!$B$9 -> 217.17727 | F15: =F14*Hypotheses!$B$9 -> 377.29822 | G15: =G14*Hypotheses!$B$9 -> 537.41916 | H15: =H14*Hypotheses!$B$9 -> 697.54011 | I15: =I14*Hypotheses!$B$9 -> 857.66105 | ... Y15: =Y14*Hypotheses!$B$9 -> 3419.5962 | Z15: =SUM(B15:Y15) -> 38391.796
A16: COMMISSION FANVUE & NET PLATEFORME
A17: Commission Fanvue (EUR) | B17: =-B15*Hypotheses!$B$8 -> -3.57696 | C17: =-C15*Hypotheses!$B$8 -> -10.28376 | D17: =-D15*Hypotheses!$B$8 -> -16.99056 | E17: =-E15*Hypotheses!$B$8 -> -32.576591 | F17: =-F15*Hypotheses!$B$8 -> -56.594733 | G17: =-G15*Hypotheses!$B$8 -> -80.612874 | H17: =-H15*Hypotheses!$B$8 -> -104.63102 | I17: =-I15*Hypotheses!$B$8 -> -128.64916 | ... Y17: =-Y15*Hypotheses!$B$8 -> -512.93943 | Z17: =SUM(B17:Y17) -> -5758.7695
A18: Net Fanvue (après commission) | B18: =B15+B17 -> 20.26944 | C18: =C15+C17 -> 58.27464 | D18: =D15+D17 -> 96.27984 | E18: =E15+E17 -> 184.60068 | F18: =F15+F17 -> 320.70349 | G18: =G15+G17 -> 456.80629 | H18: =H15+H17 -> 592.90909 | I18: =I15+I17 -> 729.0119 | ... Y18: =Y15+Y17 -> 2906.6567 | Z18: =SUM(B18:Y18) -> 32633.027
A19: FRAIS DE PRODUCTION (par modèle)
A20: Prod Mode A | B20: =-Hypotheses!$B$17 -> -80 | C20: =-Hypotheses!$B$17 -> -80 | D20: =-Hypotheses!$B$17 -> -80 | E20: =-Hypotheses!$B$17 -> -80 | F20: =-Hypotheses!$B$17 -> -80 | G20: =-Hypotheses!$B$17 -> -80 | H20: =-Hypotheses!$B$17 -> -80 | I20: =-Hypotheses!$B$17 -> -80 | ... Y20: =-Hypotheses!$B$17 -> -80 | Z20: =SUM(B20:Y20) -> -1920
A21: Prod Mode B Slot 1 (si active) | B21: =-IF(1>=Hypotheses!$B$42,Hypotheses!$B$18,0) -> 0 | C21: =-IF(2>=Hypotheses!$B$42,Hypotheses!$B$18,0) -> 0 | D21: =-IF(3>=Hypotheses!$B$42,Hypotheses!$B$18,0) -> 0 | E21: =-IF(4>=Hypotheses!$B$42,Hypotheses!$B$18,0) -> -120 | F21: =-IF(5>=Hypotheses!$B$42,Hypotheses!$B$18,0) -> -120 | G21: =-IF(6>=Hypotheses!$B$42,Hypotheses!$B$18,0) -> -120 | H21: =-IF(7>=Hypotheses!$B$42,Hypotheses!$B$18,0) -> -120 | I21: =-IF(8>=Hypotheses!$B$42,Hypotheses!$B$18,0) -> -120 | J21: =-IF(9>=Hypotheses!$B$42,Hypotheses!$B$18,0) -> -120 | K21: =-IF(10>=Hypotheses!$B$42,Hypotheses!$B$18,0) -> -120 | L21: =-IF(11>=Hypotheses!$B$42,Hypotheses!$B$18,0) -> -120 | M21: =-IF(12>=Hypotheses!$B$42,Hypotheses!$B$18,0) -> -120 | N21: =-IF(13>=Hypotheses!$B$42,Hypotheses!$B$18,0) -> -120 | O21: =-IF(14>=Hypotheses!$B$42,Hypotheses!$B$18,0) -> -120 | P21: =-IF(15>=Hypotheses!$B$42,Hypotheses!$B$18,0) -> -120 | Q21: =-IF(16>=Hypotheses!$B$42,Hypotheses!$B$18,0) -> -120 | R21: =-IF(17>=Hypotheses!$B$42,Hypotheses!$B$18,0) -> -120 | S21: =-IF(18>=Hypotheses!$B$42,Hypotheses!$B$18,0) -> -120 | T21: =-IF(19>=Hypotheses!$B$42,Hypotheses!$B$18,0) -> -120 | U21: =-IF(20>=Hypotheses!$B$42,Hypotheses!$B$18,0) -> -120 | V21: =-IF(21>=Hypotheses!$B$42,Hypotheses!$B$18,0) -> -120 | W21: =-IF(22>=Hypotheses!$B$42,Hypotheses!$B$18,0) -> -120 | X21: =-IF(23>=Hypotheses!$B$42,Hypotheses!$B$18,0) -> -120 | Y21: =-IF(24>=Hypotheses!$B$42,Hypotheses!$B$18,0) -> -120 | Z21: =SUM(B21:Y21) -> -2520
A22: Prod Mode B Slot 2 (si active) | B22: =-IF(1>=Hypotheses!$B$44,Hypotheses!$B$19,0) -> 0 | C22: =-IF(2>=Hypotheses!$B$44,Hypotheses!$B$19,0) -> 0 | D22: =-IF(3>=Hypotheses!$B$44,Hypotheses!$B$19,0) -> 0 | E22: =-IF(4>=Hypotheses!$B$44,Hypotheses!$B$19,0) -> 0 | F22: =-IF(5>=Hypotheses!$B$44,Hypotheses!$B$19,0) -> -120 | G22: =-IF(6>=Hypotheses!$B$44,Hypotheses!$B$19,0) -> -120 | H22: =-IF(7>=Hypotheses!$B$44,Hypotheses!$B$19,0) -> -120 | I22: =-IF(8>=Hypotheses!$B$44,Hypotheses!$B$19,0) -> -120 | J22: =-IF(9>=Hypotheses!$B$44,Hypotheses!$B$19,0) -> -120 | K22: =-IF(10>=Hypotheses!$B$44,Hypotheses!$B$19,0) -> -120 | L22: =-IF(11>=Hypotheses!$B$44,Hypotheses!$B$19,0) -> -120 | M22: =-IF(12>=Hypotheses!$B$44,Hypotheses!$B$19,0) -> -120 | N22: =-IF(13>=Hypotheses!$B$44,Hypotheses!$B$19,0) -> -120 | O22: =-IF(14>=Hypotheses!$B$44,Hypotheses!$B$19,0) -> -120 | P22: =-IF(15>=Hypotheses!$B$44,Hypotheses!$B$19,0) -> -120 | Q22: =-IF(16>=Hypotheses!$B$44,Hypotheses!$B$19,0) -> -120 | R22: =-IF(17>=Hypotheses!$B$44,Hypotheses!$B$19,0) -> -120 | S22: =-IF(18>=Hypotheses!$B$44,Hypotheses!$B$19,0) -> -120 | T22: =-IF(19>=Hypotheses!$B$44,Hypotheses!$B$19,0) -> -120 | U22: =-IF(20>=Hypotheses!$B$44,Hypotheses!$B$19,0) -> -120 | V22: =-IF(21>=Hypotheses!$B$44,Hypotheses!$B$19,0) -> -120 | W22: =-IF(22>=Hypotheses!$B$44,Hypotheses!$B$19,0) -> -120 | X22: =-IF(23>=Hypotheses!$B$44,Hypotheses!$B$19,0) -> -120 | Y22: =-IF(24>=Hypotheses!$B$44,Hypotheses!$B$19,0) -> -120 | Z22: =SUM(B22:Y22) -> -2400
A23: Total frais production | B23: =B20+B21+B22 -> -80 | C23: =C20+C21+C22 -> -80 | D23: =D20+D21+D22 -> -80 | E23: =E20+E21+E22 -> -200 | F23: =F20+F21+F22 -> -320 | G23: =G20+G21+G22 -> -320 | H23: =H20+H21+H22 -> -320 | I23: =I20+I21+I22 -> -320 | ... Y23: =Y20+Y21+Y22 -> -320 | Z23: =SUM(B23:Y23) -> -6840
A24: RÉPARTITION REVENUS MODÈLES (Mode B Slots 1 & 2)
A25: Net distribuable Mode B Slot 1 (EUR) | B25: =MAX(0,(B12*Hypotheses!$B$9)*(1-Hypotheses!$B$8)+B21) -> 0 | C25: =MAX(0,(C12*Hypotheses!$B$9)*(1-Hypotheses!$B$8)+C21) -> 0 | D25: =MAX(0,(D12*Hypotheses!$B$9)*(1-Hypotheses!$B$8)+D21) -> 0 | E25: =MAX(0,(E12*Hypotheses!$B$9)*(1-Hypotheses!$B$8)+E21) -> 0 | F25: =MAX(0,(F12*Hypotheses!$B$9)*(1-Hypotheses!$B$8)+F21) -> 0 | G25: =MAX(0,(G12*Hypotheses!$B$9)*(1-Hypotheses!$B$8)+G21) -> 30.946925 | H25: =MAX(0,(H12*Hypotheses!$B$9)*(1-Hypotheses!$B$8)+H21) -> 81.262567 | I25: =MAX(0,(I12*Hypotheses!$B$9)*(1-Hypotheses!$B$8)+I21) -> 131.57821 | ... Y25: =MAX(0,(Y12*Hypotheses!$B$9)*(1-Hypotheses!$B$8)+Y21) -> 936.62848 | Z25: =SUM(B25:Y25) -> 9191.9663
A26: Net distribuable Mode B Slot 2 (EUR) | B26: =MAX(0,(B13*Hypotheses!$B$9)*(1-Hypotheses!$B$8)+B22) -> 0 | C26: =MAX(0,(C13*Hypotheses!$B$9)*(1-Hypotheses!$B$8)+C22) -> 0 | D26: =MAX(0,(D13*Hypotheses!$B$9)*(1-Hypotheses!$B$8)+D22) -> 0 | E26: =MAX(0,(E13*Hypotheses!$B$9)*(1-Hypotheses!$B$8)+E22) -> 0 | F26: =MAX(0,(F13*Hypotheses!$B$9)*(1-Hypotheses!$B$8)+F22) -> 0 | G26: =MAX(0,(G13*Hypotheses!$B$9)*(1-Hypotheses!$B$8)+G22) -> 0 | H26: =MAX(0,(H13*Hypotheses!$B$9)*(1-Hypotheses!$B$8)+H22) -> 23.345885 | I26: =MAX(0,(I13*Hypotheses!$B$9)*(1-Hypotheses!$B$8)+I22) -> 71.127847 | ... Y26: =MAX(0,(Y13*Hypotheses!$B$9)*(1-Hypotheses!$B$8)+Y22) -> 835.63923 | Z26: =SUM(B26:Y26) -> 7730.8661
A27: Réversion Mode B Slot 1 (70%) | B27: =-B25*Hypotheses!$B$12 -> 0 | C27: =-C25*Hypotheses!$B$12 -> 0 | D27: =-D25*Hypotheses!$B$12 -> 0 | E27: =-E25*Hypotheses!$B$12 -> 0 | F27: =-F25*Hypotheses!$B$12 -> 0 | G27: =-G25*Hypotheses!$B$12 -> -21.662848 | H27: =-H25*Hypotheses!$B$12 -> -56.883797 | I27: =-I25*Hypotheses!$B$12 -> -92.104746 | ... Y27: =-Y25*Hypotheses!$B$12 -> -655.63993 | Z27: =SUM(B27:Y27) -> -6434.3764
A28: Réversion Mode B Slot 2 (70%) | B28: =-B26*Hypotheses!$B$13 -> 0 | C28: =-C26*Hypotheses!$B$13 -> 0 | D28: =-D26*Hypotheses!$B$13 -> 0 | E28: =-E26*Hypotheses!$B$13 -> 0 | F28: =-F26*Hypotheses!$B$13 -> 0 | G28: =-G26*Hypotheses!$B$13 -> 0 | H28: =-H26*Hypotheses!$B$13 -> -16.34212 | I28: =-I26*Hypotheses!$B$13 -> -49.789493 | ... Y28: =-Y26*Hypotheses!$B$13 -> -584.94746 | Z28: =SUM(B28:Y28) -> -5411.6062
A29: MARGE BRUTE SQWENSY (après Fanvue, prod, réversion)
A30: Marge brute Sqwensy | B30: =B18+B23+B27+B28 -> -59.73056 | C30: =C18+C23+C27+C28 -> -21.72536 | D30: =D18+D23+D27+D28 -> 16.27984 | E30: =E18+E23+E27+E28 -> -15.399318 | F30: =F18+F23+F27+F28 -> 0.70348507 | G30: =G18+G23+G27+G28 -> 115.14344 | H30: =H18+H23+H27+H28 -> 199.68318 | I30: =I18+I23+I27+I28 -> 267.11766 | ... Y30: =Y18+Y23+Y27+Y28 -> 1346.0694 | Z30: =SUM(B30:Y30) -> 13947.044
A31: FRAIS FIXES SQWENSY-HEAVEN
A32: Hosting | B32: =-Hypotheses!$B$22 -> -25 | C32: =-Hypotheses!$B$22 -> -25 | D32: =-Hypotheses!$B$22 -> -25 | E32: =-Hypotheses!$B$22 -> -25 | F32: =-Hypotheses!$B$22 -> -25 | G32: =-Hypotheses!$B$22 -> -25 | H32: =-Hypotheses!$B$22 -> -25 | I32: =-Hypotheses!$B$22 -> -25 | ... Y32: =-Hypotheses!$B$22 -> -25 | Z32: =SUM(B32:Y32) -> -600
A33: Outils / API / agent IA | B33: =-Hypotheses!$B$23 -> -40 | C33: =-Hypotheses!$B$23 -> -40 | D33: =-Hypotheses!$B$23 -> -40 | E33: =-Hypotheses!$B$23 -> -40 | F33: =-Hypotheses!$B$23 -> -40 | G33: =-Hypotheses!$B$23 -> -40 | H33: =-Hypotheses!$B$23 -> -40 | I33: =-Hypotheses!$B$23 -> -40 | ... Y33: =-Hypotheses!$B$23 -> -40 | Z33: =SUM(B33:Y33) -> -960
A34: Domaines / misc | B34: =-Hypotheses!$B$24 -> -10 | C34: =-Hypotheses!$B$24 -> -10 | D34: =-Hypotheses!$B$24 -> -10 | E34: =-Hypotheses!$B$24 -> -10 | F34: =-Hypotheses!$B$24 -> -10 | G34: =-Hypotheses!$B$24 -> -10 | H34: =-Hypotheses!$B$24 -> -10 | I34: =-Hypotheses!$B$24 -> -10 | ... Y34: =-Hypotheses!$B$24 -> -10 | Z34: =SUM(B34:Y34) -> -240
A35: Provision juridique/comptable | B35: =-Hypotheses!$B$25 -> -80 | C35: =-Hypotheses!$B$25 -> -80 | D35: =-Hypotheses!$B$25 -> -80 | E35: =-Hypotheses!$B$25 -> -80 | F35: =-Hypotheses!$B$25 -> -80 | G35: =-Hypotheses!$B$25 -> -80 | H35: =-Hypotheses!$B$25 -> -80 | I35: =-Hypotheses!$B$25 -> -80 | ... Y35: =-Hypotheses!$B$25 -> -80 | Z35: =SUM(B35:Y35) -> -1920
A36: Total frais fixes | B36: =B32+B33+B34+B35 -> -155 | C36: =C32+C33+C34+C35 -> -155 | D36: =D32+D33+D34+D35 -> -155 | E36: =E32+E33+E34+E35 -> -155 | F36: =F32+F33+F34+F35 -> -155 | G36: =G32+G33+G34+G35 -> -155 | H36: =H32+H33+H34+H35 -> -155 | I36: =I32+I33+I34+I35 -> -155 | ... Y36: =Y32+Y33+Y34+Y35 -> -155 | Z36: =SUM(B36:Y36) -> -3720
A37: EBITDA & RÉSULTAT
A38: EBITDA Heaven | B38: =B30+B36 -> -214.73056 | C38: =C30+C36 -> -176.72536 | D38: =D30+D36 -> -138.72016 | E38: =E30+E36 -> -170.39932 | F38: =F30+F36 -> -154.29651 | G38: =G30+G36 -> -39.856559 | H38: =H30+H36 -> 44.683176 | I38: =I30+I36 -> 112.11766 | ... Y38: =Y30+Y36 -> 1191.0694 | Z38: =SUM(B38:Y38) -> 10227.044
A39: Cotisations INASTI (provision approx) | B39: =-MAX(0,B38)*0.3*Hypotheses!$B$36 -> 0 | C39: =-MAX(0,C38)*0.3*Hypotheses!$B$36 -> 0 | D39: =-MAX(0,D38)*0.3*Hypotheses!$B$36 -> 0 | E39: =-MAX(0,E38)*0.3*Hypotheses!$B$36 -> 0 | F39: =-MAX(0,F38)*0.3*Hypotheses!$B$36 -> 0 | G39: =-MAX(0,G38)*0.3*Hypotheses!$B$36 -> 0 | H39: =-MAX(0,H38)*0.3*Hypotheses!$B$36 -> -2.7480153 | I39: =-MAX(0,I38)*0.3*Hypotheses!$B$36 -> -6.8952359 | ... Y39: =-MAX(0,Y38)*0.3*Hypotheses!$B$36 -> -73.250765 | Z39: =SUM(B39:Y39) -> -683.98902
A40: ISOC estimé (20 % PME simplifié) | B40: =-MAX(0,B38+B39)*Hypotheses!$B$34 -> 0 | C40: =-MAX(0,C38+C39)*Hypotheses!$B$34 -> 0 | D40: =-MAX(0,D38+D39)*Hypotheses!$B$34 -> 0 | E40: =-MAX(0,E38+E39)*Hypotheses!$B$34 -> 0 | F40: =-MAX(0,F38+F39)*Hypotheses!$B$34 -> 0 | G40: =-MAX(0,G38+G39)*Hypotheses!$B$34 -> 0 | H40: =-MAX(0,H38+H39)*Hypotheses!$B$34 -> -8.3870321 | I40: =-MAX(0,I38+I39)*Hypotheses!$B$34 -> -21.044484 | ... Y40: =-MAX(0,Y38+Y39)*Hypotheses!$B$34 -> -223.56372 | Z40: =SUM(B40:Y40) -> -2087.5567
A42: RÉSULTAT NET HEAVEN (après fiscal) | B42: =B38+B39+B40 -> -214.73056 | C42: =C38+C39+C40 -> -176.72536 | D42: =D38+D39+D40 -> -138.72016 | E42: =E38+E39+E40 -> -170.39932 | F42: =F38+F39+F40 -> -154.29651 | G42: =G38+G39+G40 -> -39.856559 | H42: =H38+H39+H40 -> 33.548128 | I42: =I38+I39+I40 -> 84.177937 | ... Y42: =Y38+Y39+Y40 -> 894.25487 | Z42: =SUM(B42:Y42) -> 7455.4985
...

Sheet Cashflow_24mois
A1: HEAVEN — Cash-flow 24 mois (scénario médian)
A2: Hypothèse : paiement Fanvue encaissé le mois suivant (délai virement/crypto).
A4: Mois | B4: M1 | C4: M2 | D4: M3 | E4: M4 | F4: M5 | G4: M6 | H4: M7 | I4: M8 | J4: M9 | K4: M10 | L4: M11 | M4: M12 | N4: M13 | O4: M14 | P4: M15 | Q4: M16 | R4: M17 | S4: M18 | T4: M19 | U4: M20 | V4: M21 | W4: M22 | X4: M23 | Y4: M24 | Z4: Total 24M
A5: ENTRÉES
A6: Encaissement Fanvue (décalé M+1) | B6: =0 -> 0 | C6: =PL_24mois!B15 -> 23.8464 | D6: =PL_24mois!C15 -> 68.5584 | E6: =PL_24mois!D15 -> 113.2704 | F6: =PL_24mois!E15 -> 217.17727 | G6: =PL_24mois!F15 -> 377.29822 | H6: =PL_24mois!G15 -> 537.41916 | I6: =PL_24mois!H15 -> 697.54011 | J6: =PL_24mois!I15 -> 857.66105 | ... Y6: =PL_24mois!X15 -> 3259.4752 | Z6: =SUM(B6:Y6) -> 34972.2
A7: SORTIES (immédiates sauf indication)
A8: Commission Fanvue (-15 %) sur encaissement | B8: =-B6*Hypotheses!$B$8 -> 0 | C8: =-C6*Hypotheses!$B$8 -> -3.57696 | D8: =-D6*Hypotheses!$B$8 -> -10.28376 | E8: =-E6*Hypotheses!$B$8 -> -16.99056 | F8: =-F6*Hypotheses!$B$8 -> -32.576591 | G8: =-G6*Hypotheses!$B$8 -> -56.594733 | H8: =-H6*Hypotheses!$B$8 -> -80.612874 | I8: =-I6*Hypotheses!$B$8 -> -104.63102 | ... Y8: =-Y6*Hypotheses!$B$8 -> -488.92128 | Z8: =SUM(B8:Y8) -> -5245.83
A9: Frais production (immédiats) | B9: =PL_24mois!B23 -> -80 | C9: =PL_24mois!C23 -> -80 | D9: =PL_24mois!D23 -> -80 | E9: =PL_24mois!E23 -> -200 | F9: =PL_24mois!F23 -> -320 | G9: =PL_24mois!G23 -> -320 | H9: =PL_24mois!H23 -> -320 | I9: =PL_24mois!I23 -> -320 | ... Y9: =PL_24mois!Y23 -> -320 | Z9: =SUM(B9:Y9) -> -6840
A10: Réversion modèles (payée M+1, après encaissement) | B10: =0 -> 0 | C10: =PL_24mois!B27+PL_24mois!B28 -> 0 | D10: =PL_24mois!C27+PL_24mois!C28 -> 0 | E10: =PL_24mois!D27+PL_24mois!D28 -> 0 | F10: =PL_24mois!E27+PL_24mois!E28 -> 0 | G10: =PL_24mois!F27+PL_24mois!F28 -> 0 | H10: =PL_24mois!G27+PL_24mois!G28 -> -21.662848 | I10: =PL_24mois!H27+PL_24mois!H28 -> -73.225916 | J10: =PL_24mois!I27+PL_24mois!I28 -> -141.89424 | ... Y10: =PL_24mois!X27+PL_24mois!X28 -> -1171.9191 | Z10: =SUM(B10:Y10) -> -10605.395
A11: Frais fixes (immédiats) | B11: =PL_24mois!B36 -> -155 | C11: =PL_24mois!C36 -> -155 | D11: =PL_24mois!D36 -> -155 | E11: =PL_24mois!E36 -> -155 | F11: =PL_24mois!F36 -> -155 | G11: =PL_24mois!G36 -> -155 | H11: =PL_24mois!H36 -> -155 | I11: =PL_24mois!I36 -> -155 | ... Y11: =PL_24mois!Y36 -> -155 | Z11: =SUM(B11:Y11) -> -3720
A12: INASTI (provisionné trimestriel) | B12: =PL_24mois!B39 -> 0 | C12: =PL_24mois!C39 -> 0 | D12: =PL_24mois!D39 -> 0 | E12: =PL_24mois!E39 -> 0 | F12: =PL_24mois!F39 -> 0 | G12: =PL_24mois!G39 -> 0 | H12: =PL_24mois!H39 -> -2.7480153 | I12: =PL_24mois!I39 -> -6.8952359 | ... Y12: =PL_24mois!Y39 -> -73.250765 | Z12: =SUM(B12:Y12) -> -683.98902
A13: ISOC (provisionné) | B13: =PL_24mois!B40 -> 0 | C13: =PL_24mois!C40 -> 0 | D13: =PL_24mois!D40 -> 0 | E13: =PL_24mois!E40 -> 0 | F13: =PL_24mois!F40 -> 0 | G13: =PL_24mois!G40 -> 0 | H13: =PL_24mois!H40 -> -8.3870321 | I13: =PL_24mois!I40 -> -21.044484 | ... Y13: =PL_24mois!Y40 -> -223.56372 | Z13: =SUM(B13:Y13) -> -2087.5567
A15: SOLDE MENSUEL CASH | B15: =B6+B8+B9+B10+B11+B12+B13 -> -235 | C15: =C6+C8+C9+C10+C11+C12+C13 -> -214.73056 | D15: =D6+D8+D9+D10+D11+D12+D13 -> -176.72536 | E15: =E6+E8+E9+E10+E11+E12+E13 -> -258.72016 | F15: =F6+F8+F9+F10+F11+F12+F13 -> -290.39932 | G15: =G6+G8+G9+G10+G11+G12+G13 -> -154.29651 | H15: =H6+H8+H9+H10+H11+H12+H13 -> -50.991606 | I15: =I6+I8+I9+I10+I11+I12+I13 -> 16.743456 | ... Y15: =Y6+Y8+Y9+Y10+Y11+Y12+Y13 -> 826.82039 | Z15: =SUM(B15:Y15) -> 5789.4292
A16: TRÉSORERIE
A17: Solde cumulé (apport initial + soldes) | B17: =Hypotheses!$B$28+B15 -> 1765 | C17: =B17+C15 -> 1550.2694 | D17: =C17+D15 -> 1373.5441 | E17: =D17+E15 -> 1114.8239 | F17: =E17+F15 -> 824.4246 | G17: =F17+G15 -> 670.12809 | H17: =G17+H15 -> 619.13648 | I17: =H17+I15 -> 635.87994 | J17: =I17+J15 -> 703.2532 | ... Y17: =X17+Y15 -> 7789.4292
A18: Alerte trésorerie (1=OK, 0=ALERTE) | B18: =IF(B17>=Hypotheses!$B$29*ABS(PL_24mois!B36),1,0) -> 1 | C18: =IF(C17>=Hypotheses!$B$29*ABS(PL_24mois!C36),1,0) -> 1 | D18: =IF(D17>=Hypotheses!$B$29*ABS(PL_24mois!D36),1,0) -> 1 | E18: =IF(E17>=Hypotheses!$B$29*ABS(PL_24mois!E36),1,0) -> 1 | F18: =IF(F17>=Hypotheses!$B$29*ABS(PL_24mois!F36),1,0) -> 1 | G18: =IF(G17>=Hypotheses!$B$29*ABS(PL_24mois!G36),1,0) -> 1 | H18: =IF(H17>=Hypotheses!$B$29*ABS(PL_24mois!H36),1,0) -> 1 | I18: =IF(I17>=Hypotheses!$B$29*ABS(PL_24mois!I36),1,0) -> 1 | ... Y18: =IF(Y17>=Hypotheses!$B$29*ABS(PL_24mois!Y36),1,0) -> 1

Sheet Scenarios
A1: HEAVEN — Scénarios comparés 12M et 24M
A2: Le scénario médian est calculé sur PL_24mois. Pess/Opt appliquent les modificateurs définis dans Hypotheses §8.
A4: Indicateur | B4: Pessimiste | C4: Médian | D4: Optimiste | E4: Commentaire
A5: CA Fanvue brut 12 mois (EUR) | B5: =SUM(PL_24mois!B15:M15)*Hypotheses!$B$56*Hypotheses!$B$57*Hypotheses!$B$58 -> 1664.1712 | C5: =SUM(PL_24mois!B15:M15) -> 7924.6247 | D5: =SUM(PL_24mois!B15:M15)*Hypotheses!$B$59*Hypotheses!$B$60*Hypotheses!$B$61 -> 19970.054 | E5: CA cumulé sur les 12 premiers mois avant commission Fanvue.
A6: CA Fanvue brut 24 mois (EUR) | B6: =SUM(PL_24mois!B15:Y15)*Hypotheses!$B$56*Hypotheses!$B$57*Hypotheses!$B$58 -> 8062.2772 | C6: =SUM(PL_24mois!B15:Y15) -> 38391.796 | D6: =SUM(PL_24mois!B15:Y15)*Hypotheses!$B$59*Hypotheses!$B$60*Hypotheses!$B$61 -> 96747.327 | E6: Ambition 24 mois. Stress-test solidité du modèle.
A7: Marge brute Sqwensy 12 mois | B7: =SUM(PL_24mois!B30:M30)*Hypotheses!$B$56*Hypotheses!$B$57*Hypotheses!$B$58 -> 471.42644 | C7: =SUM(PL_24mois!B30:M30) -> 2244.8878 | D7: =SUM(PL_24mois!B30:M30)*Hypotheses!$B$59*Hypotheses!$B$60*Hypotheses!$B$61 -> 5657.1172 | E7: Après Fanvue fee + frais production + réversion modèles.
A8: EBITDA Heaven 12 mois | B8: =SUM(PL_24mois!B38:M38)*Hypotheses!$B$56*Hypotheses!$B$57*Hypotheses!$B$58 -> 80.826437 | C8: =SUM(PL_24mois!B38:M38) -> 384.8878 | D8: =SUM(PL_24mois!B38:M38)*Hypotheses!$B$59*Hypotheses!$B$60*Hypotheses!$B$61 -> 969.91725 | E8: Après frais fixes. Indicateur clé décision go/no-go annuelle.
A9: EBITDA Heaven 24 mois | B9: =SUM(PL_24mois!B38:Y38)*Hypotheses!$B$56*Hypotheses!$B$57*Hypotheses!$B$58 -> 2147.6793 | C9: =SUM(PL_24mois!B38:Y38) -> 10227.044 | D9: =SUM(PL_24mois!B38:Y38)*Hypotheses!$B$59*Hypotheses!$B$60*Hypotheses!$B$61 -> 25772.152 | E9: Trajectoire 2 ans.
A10: Résultat net 12 mois | B10: =SUM(PL_24mois!B42:M42)*Hypotheses!$B$56*Hypotheses!$B$57*Hypotheses!$B$58 -> 13.861559 | C10: =SUM(PL_24mois!B42:M42) -> 66.007422 | D10: =SUM(PL_24mois!B42:M42)*Hypotheses!$B$59*Hypotheses!$B$60*Hypotheses!$B$61 -> 166.3387 | E10: Après INASTI et ISOC simplifié.
A11: Résultat net 24 mois | B11: =SUM(PL_24mois!B42:Y42)*Hypotheses!$B$56*Hypotheses!$B$57*Hypotheses!$B$58 -> 1565.6547 | C11: =SUM(PL_24mois!B42:Y42) -> 7455.4985 | D11: =SUM(PL_24mois!B42:Y42)*Hypotheses!$B$59*Hypotheses!$B$60*Hypotheses!$B$61 -> 18787.856 | E11: Indicateur principal de rentabilité du projet.
A13: DÉCISIONS CLÉS DÉRIVÉES
A14: Mois de dépassement franchise TVA (25 000 €, médian) | C14: =IFERROR(MATCH(TRUE(),(PL_24mois!B44:Y44>=25000),0),"— (non atteint 24M)") -> 22 | E14: Bascule TVA à préparer 1-2 mois avant.
A15: Mode B Slot 1 — rémunération 12M (alerte plafond droit à l'image) | C15: =-SUM(PL_24mois!B27:M27) -> 891.27987 | E15: Si > plafond droit à l'image → bascule indépendante complémentaire. Cf. Hypotheses.
A16: Mode B Slot 2 — rémunération 12M (alerte plafond droit à l'image) | C16: =-SUM(PL_24mois!B28:M28) -> 599.76332 | E16: Idem.
A18: LECTURE BRUTALE DU MODÈLE
A19: • Scénario pessimiste : on teste la viabilité si le funnel organique sous-performe. Si l'EBITDA 12M y est < 0, prévoir pivot ou arrêt.
A20: • Scénario médian : hypothèse de travail par défaut. Doit être réévaluée chaque mois avec les chiffres réels.
A21: • Scénario optimiste : plafond théorique. Ne PAS l'utiliser pour piloter la trésorerie ou communiquer à un tiers.
A22: • Toutes les projections PPV sont par nature volatiles. Variance intra-mois de ±40 % est normale.
A23: • Ce modèle n'intègre pas : ban Fanvue (trajectoire = 0), shadowban prolongé IG (chute rampe abonnés), évolution réglementaire IA Act UE.

Sheet Mode_C_B2B
A1: HEAVEN — Mode C : Services B2B modèles indépendantes
A2: Revenus Mode C distincts des Modes A/B. Ouverture opérationnelle cible : M9. Avant M9, ligne à zéro.
A4: HYPOTHÈSES MODE C
A5: Setup fee moyen par cliente (EUR) | B5: 1500 | C5: Fourchette 800-2500 €
A6: Subscription mensuelle moyenne (EUR) | B6: 300 | C6: Fourchette 150-500 €
A7: Commission croissance % (sur CA cliente) | B7: 0.07 | C7: Fourchette 5-10 %, optionnelle par contrat
A8: CA mensuel moyen cliente (EUR, après traction) | B8: 2500 | C8: Hypothèse : cliente générant ~30k€/an
A9: Churn mensuel Mode C | B9: 0.08 | C9: 8 % mensuel = ~60 % annuel — à challenger, stat secteur
A10: Mois d'ouverture Mode C | B10: 9 | C10: Ne pas ouvrir avant validation Modes A/B
A11: Nouvelles clientes / mois (après ouverture) | B11: 1 | C11: Conservative. 1/mois = 12/an max.
A14: P&L MODE C MENSUEL
A15: Mois | B15: M1 | C15: M2 | D15: M3 | E15: M4 | F15: M5 | G15: M6 | H15: M7 | I15: M8 | J15: M9 | K15: M10 | L15: M11 | M15: M12 | N15: M13 | O15: M14 | P15: M15 | Q15: M16 | R15: M17 | S15: M18 | T15: M19 | U15: M20 | V15: M21 | W15: M22 | X15: M23 | Y15: M24 | Z15: Total 24M
A16: Nouvelles clientes acquises | B16: =IF(1>=$B$10,$B$11,0) -> 0 | C16: =IF(2>=$B$10,$B$11,0) -> 0 | D16: =IF(3>=$B$10,$B$11,0) -> 0 | E16: =IF(4>=$B$10,$B$11,0) -> 0 | F16: =IF(5>=$B$10,$B$11,0) -> 0 | G16: =IF(6>=$B$10,$B$11,0) -> 0 | H16: =IF(7>=$B$10,$B$11,0) -> 0 | I16: =IF(8>=$B$10,$B$11,0) -> 0 | J16: =IF(9>=$B$10,$B$11,0) -> 1 | K16: =IF(10>=$B$10,$B$11,0) -> 1 | L16: =IF(11>=$B$10,$B$11,0) -> 1 | M16: =IF(12>=$B$10,$B$11,0) -> 1 | N16: =IF(13>=$B$10,$B$11,0) -> 1 | O16: =IF(14>=$B$10,$B$11,0) -> 1 | P16: =IF(15>=$B$10,$B$11,0) -> 1 | Q16: =IF(16>=$B$10,$B$11,0) -> 1 | R16: =IF(17>=$B$10,$B$11,0) -> 1 | S16: =IF(18>=$B$10,$B$11,0) -> 1 | T16: =IF(19>=$B$10,$B$11,0) -> 1 | U16: =IF(20>=$B$10,$B$11,0) -> 1 | V16: =IF(21>=$B$10,$B$11,0) -> 1 | W16: =IF(22>=$B$10,$B$11,0) -> 1 | X16: =IF(23>=$B$10,$B$11,0) -> 1 | Y16: =IF(24>=$B$10,$B$11,0) -> 1 | Z16: =SUM(B16:Y16) -> 16
A17: Clientes actives cumulées (après churn) | B17: =B16 -> 0 | C17: =B17*(1-$B$9)+C16 -> 0 | D17: =C17*(1-$B$9)+D16 -> 0 | E17: =D17*(1-$B$9)+E16 -> 0 | F17: =E17*(1-$B$9)+F16 -> 0 | G17: =F17*(1-$B$9)+G16 -> 0 | H17: =G17*(1-$B$9)+H16 -> 0 | I17: =H17*(1-$B$9)+I16 -> 0 | J17: =I17*(1-$B$9)+J16 -> 1 | ... Y17: =X17*(1-$B$9)+Y16 -> 9.2075799 | Z17: — (stock)
A19: Revenu Setup fee | B19: =B16*$B$5 -> 0 | C19: =C16*$B$5 -> 0 | D19: =D16*$B$5 -> 0 | E19: =E16*$B$5 -> 0 | F19: =F16*$B$5 -> 0 | G19: =G16*$B$5 -> 0 | H19: =H16*$B$5 -> 0 | I19: =I16*$B$5 -> 0 | ... Y19: =Y16*$B$5 -> 1500 | Z19: =SUM(B19:Y19) -> 24000
A20: Revenu Subscription | B20: =B17*$B$6 -> 0 | C20: =C17*$B$6 -> 0 | D20: =D17*$B$6 -> 0 | E20: =E17*$B$6 -> 0 | F20: =F17*$B$6 -> 0 | G20: =G17*$B$6 -> 0 | H20: =H17*$B$6 -> 0 | I20: =I17*$B$6 -> 0 | ... Y20: =Y17*$B$6 -> 2762.274 | Z20: =SUM(B20:Y20) -> 28233.85
A21: Revenu Commission croissance | B21: =B17*$B$8*$B$7 -> 0 | C21: =C17*$B$8*$B$7 -> 0 | D21: =D17*$B$8*$B$7 -> 0 | E21: =E17*$B$8*$B$7 -> 0 | F21: =F17*$B$8*$B$7 -> 0 | G21: =G17*$B$8*$B$7 -> 0 | H21: =H17*$B$8*$B$7 -> 0 | I21: =I17*$B$8*$B$7 -> 0 | ... Y21: =Y17*$B$8*$B$7 -> 1611.3265 | Z21: =SUM(B21:Y21) -> 16469.746
A22: TOTAL REVENU MODE C | B22: =B19+B20+B21 -> 0 | C22: =C19+C20+C21 -> 0 | D22: =D19+D20+D21 -> 0 | E22: =E19+E20+E21 -> 0 | F22: =F19+F20+F21 -> 0 | G22: =G19+G20+G21 -> 0 | H22: =H19+H20+H21 -> 0 | I22: =I19+I20+I21 -> 0 | ... Y22: =Y19+Y20+Y21 -> 5873.6004 | Z22: =SUM(B22:Y22) -> 68703.595
A23: COÛTS OPÉRATIONNELS MODE C
A24: Coût infra dédiée / cliente active | B24: =-B17*30 -> 0 | C24: =-C17*30 -> 0 | D24: =-D17*30 -> 0 | E24: =-E17*30 -> 0 | F24: =-F17*30 -> 0 | G24: =-G17*30 -> 0 | H24: =-H17*30 -> 0 | I24: =-I17*30 -> 0 | ... Y24: =-Y17*30 -> -276.2274 | Z24: =SUM(B24:Y24) -> -2823.385
A25: Coût temps humain (2h/mois/cliente @ 40€) | B25: =-B17*80 -> 0 | C25: =-C17*80 -> 0 | D25: =-D17*80 -> 0 | E25: =-E17*80 -> 0 | F25: =-F17*80 -> 0 | G25: =-G17*80 -> 0 | H25: =-H17*80 -> 0 | I25: =-I17*80 -> 0 | ... Y25: =-Y17*80 -> -736.60639 | Z25: =SUM(B25:Y25) -> -7529.0265
A27: MARGE BRUTE MODE C | B27: =B22+B24+B25 -> 0 | C27: =C22+C24+C25 -> 0 | D27: =D22+D24+D25 -> 0 | E27: =E22+E24+E25 -> 0 | F27: =F22+F24+F25 -> 0 | G27: =G22+G24+G25 -> 0 | H27: =H22+H24+H25 -> 0 | I27: =I22+I24+I25 -> 0 | ... Y27: =Y22+Y24+Y25 -> 4860.7666 | Z27: =SUM(B27:Y27) -> 58351.184
A29: NOTES MODE C
A30: • Mode C à ouvrir M9 uniquement si Modes A et B ont passé leurs milestones (cf. BP §9).
A31: • Hypothèse acquisition conservative (1 cliente/mois). À valider en fonction du canal d'acquisition B2B (réseau, contenu, referral).
A32: • Commission croissance à négocier par contrat — ne pas garantir un chiffre.
A33: • Le modèle NE consolide PAS Mode A/B/C — chaque mode a son P&L distinct pour clarté stratégique.
A34: • Mode C n'est PAS un SaaS. C'est du service. Ne pas projeter des marges de SaaS (80 %+) — attendre 30-50 % réaliste.

Sheet Paliers_Simulateur
A1: HEAVEN — Simulateur paliers de rémunération modèle
A2: Entre le revenu brut mensuel plateforme que la modèle génère. Le simulateur calcule le palier applicable et le net estimé modèle.
A4: INPUT SIMULATEUR
A5: Revenu brut Fanvue mensuel de la modèle (EUR) | B5: 800
A6: Frais production dédiés (EUR/mois) | B6: 120
A7: Statut (1=Salariée, 2=Étudiante, 3=Chômage, 4=Sans act., 5=Pensionnée) | B7: 1
A9: CALCULS
A10: Revenu brut annualisé plateforme | B10: =B5*12 -> 9600
A11: Net distribuable mensuel (après 15% Fanvue - frais) | B11: =B5*(1-Hypotheses!$B$8)-B6 -> 560
A12: Part modèle 70 % mensuel (brut avant fiscalité) | B12: =MAX(0,B11*Hypotheses!$B$12) -> 392
A13: Part modèle annualisée (brut avant fiscalité) | B13: =B12*12 -> 4704
A14: Palier applicable | B14: =IF(B13<1000,"P1 — Test",IF(B13<9000,"P2 — Démarrage",IF(B13<20000,"P3 — Structuration","P4 — Pro"))) -> P2 — Démarrage
A15: Voie fiscale recommandée | B15: =IF(B13<9000,"Droit à l'image",IF(B13<20000,"Indép. complémentaire (sans TVA)",IF(B13<25000,"Indép. complémentaire (sans TVA) OU principale","Indép. + TVA activée"))) -> Droit à l'image
A16: Charge fiscale estimée (% du brut modèle) | B16: =IF(B13<9000,0.15,IF(B13<20000,0.28,IF(B13<25000,0.33,0.4))) -> 0.15
A17: Net modèle estimé annualisé (après charges) | B17: =B13*(1-B16) -> 3998.4
A18: Net modèle estimé mensuel | B18: =B17/12 -> 333.2
A20: ALERTE STATUT
A21: Message | B21: =IF(B7=3,"STATUT CHÔMAGE : incompatible par défaut. Vérifier Article 48 ONEM ou Tremplin indépendant AVANT signature.",IF(B7=4,"Sans activité : indép. PRINCIPALE uniquement (cotisation min. ~800€/trim).",IF(B7=2,"Étudiante : statut étudiant-indépendant possible, cotisations réduites.",IF(B7=1,"Salariée : OK, vérifier clause exclusivité/loyauté contrat travail.","Pensionnée : indép. complémentaire OK, vérifier plafond cumul pension.")))) -> Salariée : OK, vérifier clause exclusivité/loyauté contrat travail.
A23: NOTES IMPORTANTES
A24: • Tous les chiffres fiscaux sont des ORDRES DE GRANDEUR 2024-2025. À CONFIRMER pour 2026 par comptable BE.
A25: • Palier P1/P2 : ~15% charge (régime mobilier art. 17 CIR92, taux 30% sur base après frais forfaitaires 50%).
A26: • Palier P3 : ~25-30% charge (cotisations INASTI indépendant complémentaire ~20,5% + IPP tranches progressives).
A27: • Palier P4 : ~35-45% charge (INASTI + IPP + potentiel collecte TVA 21% sur prix de vente).
A28: • Plafond droit à l'image cité ~10 000€/an (indicatif). Requalification possible si montant important et régulier.
A29: • Cotisations INASTI indépendant complémentaire QUASI-NULLES tant que revenu net < ~1 873€/an (seuil 2024).
A30: • Le modèle ne tient pas compte des éventuels plafonds de cumul spécifiques au statut (chômage, pension).
